Workbook

Sheet README
A1: Retail Inventory Control & Stock Reconciliation Workbook
A2: Nigerian FMCG distributor: beverages, noodles, cooking oil, home care and packaged food
A4: Purpose | B4: Tracks stock movements for one week, reconciles book stock to a physical count, raises reorder alerts, classifies fast and slow movers, and produces a weekly inventory report.
A5: SAMPLE DATA | B5: All product names, prices, suppliers, customers, quantities and investigation notes are fictitious illustrations for this exercise. Prices are not market quotes. Replace the blue cells with your own data.
A6: Reporting week | B6: Mon 19 Oct to Sat 24 Oct 2026 (6 trading days). Change the start date and trading days on the Settings sheet.
A7: Unit of stock | B7: Cartons / packs as stated in the Pack column on Products. Values are in Naira (₦) at cost unless stated.
A9: SHEET GUIDE
A10: Settings | B10: Week dates, safety days, alert buffers, variance tolerances, fast/slow thresholds. Edit blue cells only.
A11: Products | B11: Product master: code, supplier, pack, unit cost, selling price, supplier lead time.
A12: Transactions | B12: Daily log of purchases, sales (cash / transfer / credit), sales returns, supplier returns and damaged stock (203 sample lines).
A13: Register | B13: Inventory register. Expected closing = Opening + Stock Received + Sales Returns − Units Sold − Supplier Returns − Damaged. Enter opening stock and physical count here.
A14: Reconciliation | B14: STOCK RECONCILIATION REPORT: book vs physical, variance in units and ₦, priority flag and investigation notes.
A15: Reorder Dashboard | B15: REORDER ALERT DASHBOARD: minimum levels, alert status, suggested order quantities and values by supplier.
A16: Movers Analysis | B16: Fast / medium / slow classification using units sold and weekly stock turnover.
A17: Sales Summary | B17: Pivot-style SUMIFS tables: sales by day and payment type, and by category.
A18: Weekly Report | B18: WEEKLY INVENTORY PERFORMANCE SUMMARY: KPIs, losses, movers, auto-generated observations and charts.
A20: COLOUR CODE
A21: Blue text on yellow | B21: Input cell: you type or paste here.
A22: Black text | B22: Formula: do not overwrite.
A24: HOW TO ADD DATA
A25: 1. New transactions | B25: Add rows at the bottom of Transactions (up to row 1000). Enter date, product code, type, quantity, party and terms. Copy the formulas in columns D, E, J and K down from the row above.
A26: 2. Next week | B26: Update Settings start date, then set new Opening Stock (last week’s physical count) and clear the Physical Count column on Register.
A27: 3. Real PivotTable | B27: Select Transactions!A5:L(last row) > Insert > PivotTable. Suggested layout: Rows = Product Name, Columns = Txn Type, Values = Sum of Qty. This file uses SUMIFS tables instead because PivotTables cannot be generated programmatically here.
A29: KEY ASSUMPTIONS
A30: Valuation | B30: Purchases, supplier returns, damaged stock and variances are valued at unit cost. Sales and sales returns are valued at list selling price (no discounts modelled).
A31: Stock on hand | B31: Reorder Dashboard uses the physical count where entered, otherwise the book balance.
A32: Minimum stock | B32: Calculated as average daily sales × (supplier lead time + safety days). Type a figure in the Override column on Reorder Dashboard to set your own.
A33: Turnover | B33: Weekly turnover = units sold ÷ average of opening and closing stock. Annualised figure multiplies by 52 and is indicative only.
A34: Potential loss | B34: Stock shortages + damaged stock, both at cost. Overages are not netted off; supplier returns are excluded because they are recoverable by credit note.
A35: Classification | B35: Thresholds are set on Settings. They are practical starting points, not an industry standard. Tune them to your business.

Sheet Weekly Report
A1: =Settings!B4&" - Weekly Inventory Performance Summary" -> Eko Provisions Distribution Ltd (sample) - Weekly Inventory Performance Summary
A2: ="Week: "&TEXT(Settings!B5,"dd mmm yyyy")&" to "&TEXT(Settings!B7,"dd mmm yyyy")&" | Values in ₦ at cost unless stated | Sample data" -> Week: 19 Oct 2026 to 24 Oct 2026 | Values in ₦ at cost unless stated | Sample data
A4: 1. Sales and margin
A5: Gross sales (₦ at selling price) | B5: ='Sales Summary'!H12 -> 6588900
A6: Cash sales | B6: ='Sales Summary'!E12 -> 2077800 | C6: =IFERROR(B6/$B$5,0) -> 0.31534854
A7: Transfer sales | B7: ='Sales Summary'!F12 -> 1972900 | C7: =IFERROR(B7/$B$5,0) -> 0.29942783
A8: Credit sales (receivable) | B8: ='Sales Summary'!G12 -> 2538200 | C8: =IFERROR(B8/$B$5,0) -> 0.38522363
A9: Sales returns (₦ at selling price) | B9: ='Sales Summary'!I12 -> 139100
A10: Cost of goods sold (net of returns) | B10: =SUMPRODUCT(Register!G6:G23-Register!F6:F23,Register!M6:M23) -> 5804900
A11: Net sales | B11: =B5-B9 -> 6449800
A12: Gross margin (₦) | B12: =B11-B10 -> 644900
A13: Gross margin % | B13: =IFERROR(B12/B11,0) -> 0.099987597
A15: 2. Stock position
A16: Opening stock value | B16: =SUMPRODUCT(Register!D6:D23,Register!M6:M23) -> 10345900
A17: Purchases received | B17: =SUMPRODUCT(Register!E6:E23,Register!M6:M23) -> 3308300
A18: Closing stock value: book | B18: =SUMPRODUCT(Register!J6:J23,Register!M6:M23) -> 7672800
A19: Closing stock value: physical count | B19: =SUMPRODUCT(Register!K6:K23,Register!M6:M23) -> 7585900
A20: Stock availability (% of SKUs in stock) | B20: =COUNTIF('Reorder Dashboard'!E9:E26,">0")/COUNTA('Reorder Dashboard'!A9:A26) -> 0.94444444
A21: SKUs in stock-out | B21: ='Reorder Dashboard'!A5 -> 1
A22: SKUs at or below minimum (reorder now) | B22: ='Reorder Dashboard'!B5 -> 4
A23: SKUs approaching minimum | B23: ='Reorder Dashboard'!C5 -> 3
A24: Reorder requirement (₦ at cost) | B24: ='Reorder Dashboard'!E5 -> 3977800
A26: 3. Control: variances and potential losses
A27: SKUs with a stock variance | B27: =Reconciliation!B6+Reconciliation!B7 -> 7
A28: Stock record accuracy (% SKUs matching) | B28: =Reconciliation!B8 -> 0.61111111
A29: Shortage value | B29: =Reconciliation!E4 -> -112800
A30: Overage value | B30: =Reconciliation!E5 -> 25900
A31: Net variance | B31: =Reconciliation!E6 -> -86900
A32: Damaged stock | B32: =Reconciliation!E7 -> 123300
A33: Supplier returns (recoverable by credit note; not a loss) | B33: =SUMPRODUCT(Register!H6:H23,Register!M6:M23) -> 53200
A34: Total potential loss (shortages + damaged) | B34: =-B29+B32 -> 236100 | C34: =IFERROR(B34/B11,0) -> 0.036605786
A36: 4. Fast and slow movers
A37: Top 5 by units sold | B37: Units Sold | C37: Weekly Turnover | D37: Classification
A38: =INDEX('Movers Analysis'!$C$6:$C$23,MATCH(1,'Movers Analysis'!$A$6:$A$23,0)) -> Instant Noodles Chicken 70g | B38: =INDEX('Movers Analysis'!$D$6:$D$23,MATCH(1,'Movers Analysis'!$A$6:$A$23,0)) -> 90 | C38: =INDEX('Movers Analysis'!$H$6:$H$23,MATCH(1,'Movers Analysis'!$A$6:$A$23,0)) -> 0.80717489 | D38: =INDEX('Movers Analysis'!$K$6:$K$23,MATCH(1,'Movers Analysis'!$A$6:$A$23,0)) -> Medium
A39: =INDEX('Movers Analysis'!$C$6:$C$23,MATCH(2,'Movers Analysis'!$A$6:$A$23,0)) -> Table Water 75cl | B39: =INDEX('Movers Analysis'!$D$6:$D$23,MATCH(2,'Movers Analysis'!$A$6:$A$23,0)) -> 72 | C39: =INDEX('Movers Analysis'!$H$6:$H$23,MATCH(2,'Movers Analysis'!$A$6:$A$23,0)) -> 1.210084 | D39: =INDEX('Movers Analysis'!$K$6:$K$23,MATCH(2,'Movers Analysis'!$A$6:$A$23,0)) -> Fast-moving
A40: =INDEX('Movers Analysis'!$C$6:$C$23,MATCH(3,'Movers Analysis'!$A$6:$A$23,0)) -> Cola Soft Drink 50cl PET | B40: =INDEX('Movers Analysis'!$D$6:$D$23,MATCH(3,'Movers Analysis'!$A$6:$A$23,0)) -> 60 | C40: =INDEX('Movers Analysis'!$H$6:$H$23,MATCH(3,'Movers Analysis'!$A$6:$A$23,0)) -> 2.1428571 | D40: =INDEX('Movers Analysis'!$K$6:$K$23,MATCH(3,'Movers Analysis'!$A$6:$A$23,0)) -> Fast-moving
A41: =INDEX('Movers Analysis'!$C$6:$C$23,MATCH(4,'Movers Analysis'!$A$6:$A$23,0)) -> Instant Noodles Onion 70g | B41: =INDEX('Movers Analysis'!$D$6:$D$23,MATCH(4,'Movers Analysis'!$A$6:$A$23,0)) -> 54 | C41: =INDEX('Movers Analysis'!$H$6:$H$23,MATCH(4,'Movers Analysis'!$A$6:$A$23,0)) -> 4 | D41: =INDEX('Movers Analysis'!$K$6:$K$23,MATCH(4,'Movers Analysis'!$A$6:$A$23,0)) -> Fast-moving
A42: =INDEX('Movers Analysis'!$C$6:$C$23,MATCH(5,'Movers Analysis'!$A$6:$A$23,0)) -> Orange Soft Drink 50cl PET | B42: =INDEX('Movers Analysis'!$D$6:$D$23,MATCH(5,'Movers Analysis'!$A$6:$A$23,0)) -> 42 | C42: =INDEX('Movers Analysis'!$H$6:$H$23,MATCH(5,'Movers Analysis'!$A$6:$A$23,0)) -> 1.4736842 | D42: =INDEX('Movers Analysis'!$K$6:$K$23,MATCH(5,'Movers Analysis'!$A$6:$A$23,0)) -> Fast-moving
A44: Slowest 5 by turnover | B44: Units Sold | C44: Weekly Turnover | D44: Classification
A45: =INDEX('Movers Analysis'!$C$6:$C$23,MATCH(1,'Movers Analysis'!$L$6:$L$23,0)) -> Table Salt 500g | B45: =INDEX('Movers Analysis'!$D$6:$D$23,MATCH(1,'Movers Analysis'!$L$6:$L$23,0)) -> 4 | C45: =INDEX('Movers Analysis'!$H$6:$H$23,MATCH(1,'Movers Analysis'!$L$6:$L$23,0)) -> 0.18181818 | D45: =INDEX('Movers Analysis'!$K$6:$K$23,MATCH(1,'Movers Analysis'!$L$6:$L$23,0)) -> Slow-moving
...

Sheet Settings
A1: Settings and Assumptions
A2: Edit blue cells only. Every sheet reads these values.
A3: Parameter | B3: Value | C3: Note / source
A4: Business name | B4: Eko Provisions Distribution Ltd (sample) | C4: Fictitious business name for the exercise
A5: Week start date (Monday) | B5: 46314 | C5: Assumption: reporting week 19 to 24 Oct 2026
A6: Trading days in week | B6: 6 | C6: Assumption: Mon to Sat; Sunday closed
A7: Week end date | B7: =B5+B6-1 -> 46319 | C7: Formula: start + trading days − 1
A8: Safety stock (days of sales) | B8: 2 | C8: Assumption: buffer against late supplier deliveries
A9: Target stock cover when reordering (days) | B9: 14 | C9: Assumption: order up to 14 days of average sales
A10: "Approaching" alert buffer above minimum | B10: 0.25 | C10: Assumption: warn when stock is within 25% above minimum
A11: Variance tolerance (% of book balance) | B11: 0.05 | C11: Assumption: variances at or above 5% of book balance are flagged HIGH
A12: High-priority variance value (₦ at cost) | B12: 20000 | C12: Assumption: variances at or above ₦20,000 are flagged HIGH
A13: Fast-moving: weekly turnover at or above | B13: 1 | C13: Assumption: stock turns over at least once a week
A14: Slow-moving: weekly turnover below | B14: 0.5 | C14: Assumption: more than two weeks of stock on hand

Sheet Products
A1: Product Master
A2: Rows 6 to 60 are read by other sheets. Prices are illustrative (sample data).
A5: Product Code | B5: Product Name | C5: Category | D5: Supplier | E5: Pack Unit | F5: Unit Cost (₦) | G5: Selling Price (₦) | H5: Supplier Lead Time (days)
A6: BEV001 | B6: Cola Soft Drink 50cl PET | C6: Beverages | D6: Apapa Beverages Depot | E6: Carton of 12 | F6: 5200 | G6: 5900 | H6: 2
A7: BEV002 | B7: Orange Soft Drink 50cl PET | C7: Beverages | D7: Apapa Beverages Depot | E7: Carton of 12 | F7: 5200 | G7: 5900 | H7: 2
A8: BEV003 | B8: Table Water 75cl | C8: Beverages | D8: Apapa Beverages Depot | E8: Pack of 12 | F8: 1900 | G8: 2300 | H8: 2
A9: BEV004 | B9: Malt Drink 33cl Can | C9: Beverages | D9: Apapa Beverages Depot | E9: Carton of 24 | F9: 9800 | G9: 11200 | H9: 2
A10: NDL001 | B10: Instant Noodles Chicken 70g | C10: Noodles & Pasta | D10: Mushin Noodles & Foods Ltd | E10: Carton of 40 | F10: 7600 | G10: 8400 | H10: 3
A11: NDL002 | B11: Instant Noodles Onion 70g | C11: Noodles & Pasta | D11: Mushin Noodles & Foods Ltd | E11: Carton of 40 | F11: 7700 | G11: 8500 | H11: 3
A12: NDL003 | B12: Spaghetti 500g | C12: Noodles & Pasta | D12: Mushin Noodles & Foods Ltd | E12: Carton of 20 | F12: 11500 | G12: 12800 | H12: 3
A13: OIL001 | B13: Vegetable Oil 5L | C13: Cooking Oil | D13: Ikorodu Oil Mills (Agent) | E13: Carton of 4 | F13: 38000 | G13: 41500 | H13: 4
A14: OIL002 | B14: Vegetable Oil 1L | C14: Cooking Oil | D14: Ikorodu Oil Mills (Agent) | E14: Carton of 12 | F14: 36000 | G14: 39000 | H14: 4
A15: DET001 | B15: Detergent Powder 900g | C15: Home Care | D15: Oshodi Home Care Supplies | E15: Carton of 12 | F15: 14400 | G15: 16200 | H15: 3
A16: DET002 | B16: Detergent Powder 400g | C16: Home Care | D16: Oshodi Home Care Supplies | E16: Carton of 24 | F16: 17000 | G16: 19000 | H16: 3
A17: DET003 | B17: Laundry Bar Soap | C17: Home Care | D17: Oshodi Home Care Supplies | E17: Carton of 20 | F17: 9000 | G17: 10200 | H17: 3
... A23: FDS006 | B23: Cocoa Beverage Powder 400g | C23: Packaged Food | D23: Idumota Dry Goods Traders | E23: Carton of 12 | F23: 21000 | G23: 23500 | H23: 5

Sheet Transactions
A1: Daily Stock Movements
A2: Type must be: Purchase, Sale, Sales Return, Supplier Return or Damaged. Quantities are always positive; the Register applies the sign.
A3: Add new rows below the last line (to row 1000) and copy formulas in columns D, E, J, K down. Sale lines need Terms (Cash / Transfer / Credit).
A5: Date | B5: Txn Ref | C5: Product Code | D5: Product Name | E5: Category | F5: Txn Type | G5: Qty (cartons) | H5: Customer / Supplier | I5: Terms | J5: Unit Value (₦) | K5: Value (₦) | L5: Remarks
A6: 46314 | B6: TX-0001 | C6: BEV001 | D6: =IFERROR(INDEX(Products!$B$6:$B$60,MATCH(C6,Products!$A$6:$A$60,0)),"") -> Cola Soft Drink 50cl PET | E6: =IFERROR(INDEX(Products!$C$6:$C$60,MATCH(C6,Products!$A$6:$A$60,0)),"") -> Beverages | F6: Purchase | G6: 27 | H6: Apapa Beverages Depot | I6: Credit | J6: =IFERROR(IF(OR(F6="Sale",F6="Sales Return"),INDEX(Products!$G$6:$G$60,MATCH(C6,Products!$A$6:$A$60,0)),INDEX(Products!$F$6:$F$60,MATCH(C6,Products!$A$6:$A$60,0))),0) -> 5200 | K6: =G6*J6 -> 140400 | L6: Delivery note DN-2535
A7: 46314 | B7: TX-0002 | C7: BEV002 | D7: =IFERROR(INDEX(Products!$B$6:$B$60,MATCH(C7,Products!$A$6:$A$60,0)),"") -> Orange Soft Drink 50cl PET | E7: =IFERROR(INDEX(Products!$C$6:$C$60,MATCH(C7,Products!$A$6:$A$60,0)),"") -> Beverages | F7: Purchase | G7: 36 | H7: Apapa Beverages Depot | I7: Credit | J7: =IFERROR(IF(OR(F7="Sale",F7="Sales Return"),INDEX(Products!$G$6:$G$60,MATCH(C7,Products!$A$6:$A$60,0)),INDEX(Products!$F$6:$F$60,MATCH(C7,Products!$A$6:$A$60,0))),0) -> 5200 | K7: =G7*J7 -> 187200 | L7: Delivery note DN-2300
A8: 46314 | B8: TX-0003 | C8: BEV003 | D8: =IFERROR(INDEX(Products!$B$6:$B$60,MATCH(C8,Products!$A$6:$A$60,0)),"") -> Table Water 75cl | E8: =IFERROR(INDEX(Products!$C$6:$C$60,MATCH(C8,Products!$A$6:$A$60,0)),"") -> Beverages | F8: Purchase | G8: 33 | H8: Apapa Beverages Depot | I8: Cash | J8: =IFERROR(IF(OR(F8="Sale",F8="Sales Return"),INDEX(Products!$G$6:$G$60,MATCH(C8,Products!$A$6:$A$60,0)),INDEX(Products!$F$6:$F$60,MATCH(C8,Products!$A$6:$A$60,0))),0) -> 1900 | K8: =G8*J8 -> 62700 | L8: Delivery note DN-2426
A9: 46314 | B9: TX-0004 | C9: DET001 | D9: =IFERROR(INDEX(Products!$B$6:$B$60,MATCH(C9,Products!$A$6:$A$60,0)),"") -> Detergent Powder 900g | E9: =IFERROR(INDEX(Products!$C$6:$C$60,MATCH(C9,Products!$A$6:$A$60,0)),"") -> Home Care | F9: Purchase | G9: 24 | H9: Oshodi Home Care Supplies | I9: Credit | J9: =IFERROR(IF(OR(F9="Sale",F9="Sales Return"),INDEX(Products!$G$6:$G$60,MATCH(C9,Products!$A$6:$A$60,0)),INDEX(Products!$F$6:$F$60,MATCH(C9,Products!$A$6:$A$60,0))),0) -> 14400 | K9: =G9*J9 -> 345600 | L9: Delivery note DN-2256
A10: 46314 | B10: TX-0005 | C10: FDS001 | D10: =IFERROR(INDEX(Products!$B$6:$B$60,MATCH(C10,Products!$A$6:$A$60,0)),"") -> Evaporated Milk 160g Tin | E10: =IFERROR(INDEX(Products!$C$6:$C$60,MATCH(C10,Products!$A$6:$A$60,0)),"") -> Packaged Food | F10: Purchase | G10: 14 | H10: Idumota Dry Goods Traders | I10: Credit | J10: =IFERROR(IF(OR(F10="Sale",F10="Sales Return"),INDEX(Products!$G$6:$G$60,MATCH(C10,Products!$A$6:$A$60,0)),INDEX(Products!$F$6:$F$60,MATCH(C10,Products!$A$6:$A$60,0))),0) -> 28000 | K10: =G10*J10 -> 392000 | L10: Delivery note DN-2660
A11: 46314 | B11: TX-0006 | C11: FDS002 | D11: =IFERROR(INDEX(Products!$B$6:$B$60,MATCH(C11,Products!$A$6:$A$60,0)),"") -> Tomato Paste 70g Sachet | E11: =IFERROR(INDEX(Products!$C$6:$C$60,MATCH(C11,Products!$A$6:$A$60,0)),"") -> Packaged Food | F11: Purchase | G11: 20 | H11: Idumota Dry Goods Traders | I11: Credit | J11: =IFERROR(IF(OR(F11="Sale",F11="Sales Return"),INDEX(Products!$G$6:$G$60,MATCH(C11,Products!$A$6:$A$60,0)),INDEX(Products!$F$6:$F$60,MATCH(C11,Products!$A$6:$A$60,0))),0) -> 15500 | K11: =G11*J11 -> 310000 | L11: Delivery note DN-2104
A12: 46314 | B12: TX-0007 | C12: NDL001 | D12: =IFERROR(INDEX(Products!$B$6:$B$60,MATCH(C12,Products!$A$6:$A$60,0)),"") -> Instant Noodles Chicken 70g | E12: =IFERROR(INDEX(Products!$C$6:$C$60,MATCH(C12,Products!$A$6:$A$60,0)),"") -> Noodles & Pasta | F12: Purchase | G12: 40 | H12: Mushin Noodles & Foods Ltd | I12: Credit | J12: =IFERROR(IF(OR(F12="Sale",F12="Sales Return"),INDEX(Products!$G$6:$G$60,MATCH(C12,Products!$A$6:$A$60,0)),INDEX(Products!$F$6:$F$60,MATCH(C12,Products!$A$6:$A$60,0))),0) -> 7600 | K12: =G12*J12 -> 304000 | L12: Delivery note DN-2301
A13: 46314 | B13: TX-0008 | C13: NDL002 | D13: =IFERROR(INDEX(Products!$B$6:$B$60,MATCH(C13,Products!$A$6:$A$60,0)),"") -> Instant Noodles Onion 70g | E13: =IFERROR(INDEX(Products!$C$6:$C$60,MATCH(C13,Products!$A$6:$A$60,0)),"") -> Noodles & Pasta | F13: Purchase | G13: 29 | H13: Mushin Noodles & Foods Ltd | I13: Cash | J13: =IFERROR(IF(OR(F13="Sale",F13="Sales Return"),INDEX(Products!$G$6:$G$60,MATCH(C13,Products!$A$6:$A$60,0)),INDEX(Products!$F$6:$F$60,MATCH(C13,Products!$A$6:$A$60,0))),0) -> 7700 | K13: =G13*J13 -> 223300 | L13: Delivery note DN-2600
A14: 46314 | B14: TX-0009 | C14: OIL001 | D14: =IFERROR(INDEX(Products!$B$6:$B$60,MATCH(C14,Products!$A$6:$A$60,0)),"") -> Vegetable Oil 5L | E14: =IFERROR(INDEX(Products!$C$6:$C$60,MATCH(C14,Products!$A$6:$A$60,0)),"") -> Cooking Oil | F14: Purchase | G14: 22 | H14: Ikorodu Oil Mills (Agent) | I14: Cash | J14: =IFERROR(IF(OR(F14="Sale",F14="Sales Return"),INDEX(Products!$G$6:$G$60,MATCH(C14,Products!$A$6:$A$60,0)),INDEX(Products!$F$6:$F$60,MATCH(C14,Products!$A$6:$A$60,0))),0) -> 38000 | K14: =G14*J14 -> 836000 | L14: Delivery note DN-2258
A15: 46314 | B15: TX-0010 | C15: BEV001 | D15: =IFERROR(INDEX(Products!$B$6:$B$60,MATCH(C15,Products!$A$6:$A$60,0)),"") -> Cola Soft Drink 50cl PET | E15: =IFERROR(INDEX(Products!$C$6:$C$60,MATCH(C15,Products!$A$6:$A$60,0)),"") -> Beverages | F15: Sale | G15: 2 | H15: Sunrise Supermarket, Yaba | I15: Credit | J15: =IFERROR(IF(OR(F15="Sale",F15="Sales Return"),INDEX(Products!$G$6:$G$60,MATCH(C15,Products!$A$6:$A$60,0)),INDEX(Products!$F$6:$F$60,MATCH(C15,Products!$A$6:$A$60,0))),0) -> 5900 | K15: =G15*J15 -> 11800
A16: 46314 | B16: TX-0011 | C16: BEV001 | D16: =IFERROR(INDEX(Products!$B$6:$B$60,MATCH(C16,Products!$A$6:$A$60,0)),"") -> Cola Soft Drink 50cl PET | E16: =IFERROR(INDEX(Products!$C$6:$C$60,MATCH(C16,Products!$A$6:$A$60,0)),"") -> Beverages | F16: Sale | G16: 4 | H16: Madam Ngozi Shop, Oshodi | I16: Credit | J16: =IFERROR(IF(OR(F16="Sale",F16="Sales Return"),INDEX(Products!$G$6:$G$60,MATCH(C16,Products!$A$6:$A$60,0)),INDEX(Products!$F$6:$F$60,MATCH(C16,Products!$A$6:$A$60,0))),0) -> 5900 | K16: =G16*J16 -> 23600
A17: 46314 | B17: TX-0012 | C17: BEV001 | D17: =IFERROR(INDEX(Products!$B$6:$B$60,MATCH(C17,Products!$A$6:$A$60,0)),"") -> Cola Soft Drink 50cl PET | E17: =IFERROR(INDEX(Products!$C$6:$C$60,MATCH(C17,Products!$A$6:$A$60,0)),"") -> Beverages | F17: Sale | G17: 3 | H17: Alhaji Bello Stores, Idumota | I17: Transfer | J17: =IFERROR(IF(OR(F17="Sale",F17="Sales Return"),INDEX(Products!$G$6:$G$60,MATCH(C17,Products!$A$6:$A$60,0)),INDEX(Products!$F$6:$F$60,MATCH(C17,Products!$A$6:$A$60,0))),0) -> 5900 | K17: =G17*J17 -> 17700
A18: 46314 | B18: TX-0013 | C18: BEV002 | D18: =IFERROR(INDEX(Products!$B$6:$B$60,MATCH(C18,Products!$A$6:$A$60,0)),"") -> Orange Soft Drink 50cl PET | E18: =IFERROR(INDEX(Products!$C$6:$C$60,MATCH(C18,Products!$A$6:$A$60,0)),"") -> Beverages | F18: Sale | G18: 6 | H18: Sunrise Supermarket, Yaba | I18: Transfer | J18: =IFERROR(IF(OR(F18="Sale",F18="Sales Return"),INDEX(Products!$G$6:$G$60,MATCH(C18,Products!$A$6:$A$60,0)),INDEX(Products!$F$6:$F$60,MATCH(C18,Products!$A$6:$A$60,0))),0) -> 5900 | K18: =G18*J18 -> 35400
A19: 46314 | B19: TX-0014 | C19: BEV003 | D19: =IFERROR(INDEX(Products!$B$6:$B$60,MATCH(C19,Products!$A$6:$A$60,0)),"") -> Table Water 75cl | E19: =IFERROR(INDEX(Products!$C$6:$C$60,MATCH(C19,Products!$A$6:$A$60,0)),"") -> Beverages | F19: Sale | G19: 12 | H19: Sunrise Supermarket, Yaba | I19: Transfer | J19: =IFERROR(IF(OR(F19="Sale",F19="Sales Return"),INDEX(Products!$G$6:$G$60,MATCH(C19,Products!$A$6:$A$60,0)),INDEX(Products!$F$6:$F$60,MATCH(C19,Products!$A$6:$A$60,0))),0) -> 2300 | K19: =G19*J19 -> 27600
A20: 46314 | B20: TX-0015 | C20: BEV004 | D20: =IFERROR(INDEX(Products!$B$6:$B$60,MATCH(C20,Products!$A$6:$A$60,0)),"") -> Malt Drink 33cl Can | E20: =IFERROR(INDEX(Products!$C$6:$C$60,MATCH(C20,Products!$A$6:$A$60,0)),"") -> Beverages | F20: Sale | G20: 1 | H20: Sunrise Supermarket, Yaba | I20: Credit | J20: =IFERROR(IF(OR(F20="Sale",F20="Sales Return"),INDEX(Products!$G$6:$G$60,MATCH(C20,Products!$A$6:$A$60,0)),INDEX(Products!$F$6:$F$60,MATCH(C20,Products!$A$6:$A$60,0))),0) -> 11200 | K20: =G20*J20 -> 11200
A21: 46314 | B21: TX-0016 | C21: BEV004 | D21: =IFERROR(INDEX(Products!$B$6:$B$60,MATCH(C21,Products!$A$6:$A$60,0)),"") -> Malt Drink 33cl Can | E21: =IFERROR(INDEX(Products!$C$6:$C$60,MATCH(C21,Products!$A$6:$A$60,0)),"") -> Beverages | F21: Sale | G21: 1 | H21: Ebenezer Provision Store, Ajegunle | I21: Cash | J21: =IFERROR(IF(OR(F21="Sale",F21="Sales Return"),INDEX(Products!$G$6:$G$60,MATCH(C21,Products!$A$6:$A$60,0)),INDEX(Products!$F$6:$F$60,MATCH(C21,Products!$A$6:$A$60,0))),0) -> 11200 | K21: =G21*J21 -> 11200
A22: 46314 | B22: TX-0017 | C22: BEV004 | D22: =IFERROR(INDEX(Products!$B$6:$B$60,MATCH(C22,Products!$A$6:$A$60,0)),"") -> Malt Drink 33cl Can | E22: =IFERROR(INDEX(Products!$C$6:$C$60,MATCH(C22,Products!$A$6:$A$60,0)),"") -> Beverages | F22: Sale | G22: 1 | H22: Sunrise Supermarket, Yaba | I22: Credit | J22: =IFERROR(IF(OR(F22="Sale",F22="Sales Return"),INDEX(Products!$G$6:$G$60,MATCH(C22,Products!$A$6:$A$60,0)),INDEX(Products!$F$6:$F$60,MATCH(C22,Products!$A$6:$A$60,0))),0) -> 11200 | K22: =G22*J22 -> 11200
A23: 46314 | B23: TX-0018 | C23: DET001 | D23: =IFERROR(INDEX(Products!$B$6:$B$60,MATCH(C23,Products!$A$6:$A$60,0)),"") -> Detergent Powder 900g | E23: =IFERROR(INDEX(Products!$C$6:$C$60,MATCH(C23,Products!$A$6:$A$60,0)),"") -> Home Care | F23: Sale | G23: 2 | H23: Alhaji Bello Stores, Idumota | I23: Credit | J23: =IFERROR(IF(OR(F23="Sale",F23="Sales Return"),INDEX(Products!$G$6:$G$60,MATCH(C23,Products!$A$6:$A$60,0)),INDEX(Products!$F$6:$F$60,MATCH(C23,Products!$A$6:$A$60,0))),0) -> 16200 | K23: =G23*J23 -> 32400
A24: 46314 | B24: TX-0019 | C24: DET001 | D24: =IFERROR(INDEX(Products!$B$6:$B$60,MATCH(C24,Products!$A$6:$A$60,0)),"") -> Detergent Powder 900g | E24: =IFERROR(INDEX(Products!$C$6:$C$60,MATCH(C24,Products!$A$6:$A$60,0)),"") -> Home Care | F24: Sale | G24: 3 | H24: Oluwaseun Mini-Mart, Surulere | I24: Transfer | J24: =IFERROR(IF(OR(F24="Sale",F24="Sales Return"),INDEX(Products!$G$6:$G$60,MATCH(C24,Products!$A$6:$A$60,0)),INDEX(Products!$F$6:$F$60,MATCH(C24,Products!$A$6:$A$60,0))),0) -> 16200 | K24: =G24*J24 -> 48600
A25: 46314 | B25: TX-0020 | C25: DET002 | D25: =IFERROR(INDEX(Products!$B$6:$B$60,MATCH(C25,Products!$A$6:$A$60,0)),"") -> Detergent Powder 400g | E25: =IFERROR(INDEX(Products!$C$6:$C$60,MATCH(C25,Products!$A$6:$A$60,0)),"") -> Home Care | F25: Sale | G25: 2 | H25: Mama Chidi Provisions, Mushin | I25: Cash | J25: =IFERROR(IF(OR(F25="Sale",F25="Sales Return"),INDEX(Products!$G$6:$G$60,MATCH(C25,Products!$A$6:$A$60,0)),INDEX(Products!$F$6:$F$60,MATCH(C25,Products!$A$6:$A$60,0))),0) -> 19000 | K25: =G25*J25 -> 38000
A26: 46314 | B26: TX-0021 | C26: DET002 | D26: =IFERROR(INDEX(Products!$B$6:$B$60,MATCH(C26,Products!$A$6:$A$60,0)),"") -> Detergent Powder 400g | E26: =IFERROR(INDEX(Products!$C$6:$C$60,MATCH(C26,Products!$A$6:$A$60,0)),"") -> Home Care | F26: Sale | G26: 1 | H26: Greenfield Supermarket, Ikeja | I26: Credit | J26: =IFERROR(IF(OR(F26="Sale",F26="Sales Return"),INDEX(Products!$G$6:$G$60,MATCH(C26,Products!$A$6:$A$60,0)),INDEX(Products!$F$6:$F$60,MATCH(C26,Products!$A$6:$A$60,0))),0) -> 19000 | K26: =G26*J26 -> 19000
... A47: 46314 | B47: TX-0042 | C47: OIL002 | D47: =IFERROR(INDEX(Products!$B$6:$B$60,MATCH(C47,Products!$A$6:$A$60,0)),"") -> Vegetable Oil 1L | E47: =IFERROR(INDEX(Products!$C$6:$C$60,MATCH(C47,Products!$A$6:$A$60,0)),"") -> Cooking Oil | F47: Sale | G47: 1 | H47: Mama Chidi Provisions, Mushin | I47: Cash | J47: =IFERROR(IF(OR(F47="Sale",F47="Sales Return"),INDEX(Products!$G$6:$G$60,MATCH(C47,Products!$A$6:$A$60,0)),INDEX(Products!$F$6:$F$60,MATCH(C47,Products!$A$6:$A$60,0))),0) -> 39000 | K47: =G47*J47 -> 39000
A48: 46314 | B48: TX-0043 | C48: BEV002 | D48: =IFERROR(INDEX(Products!$B$6:$B$60,MATCH(C48,Products!$A$6:$A$60,0)),"") -> Orange Soft Drink 50cl PET | E48: =IFERROR(INDEX(Products!$C$6:$C$60,MATCH(C48,Products!$A$6:$A$60,0)),"") -> Beverages | F48: Damaged | G48: 1 | H48: Warehouse | J48: =IFERROR(IF(OR(F48="Sale",F48="Sales Return"),INDEX(Products!$G$6:$G$60,MATCH(C48,Products!$A$6:$A$60,0)),INDEX(Products!$F$6:$F$60,MATCH(C48,Products!$A$6:$A$60,0))),0) -> 5200 | K48: =G48*J48 -> 5200 | L48: Broken bottles during offloading
A49: 46315 | B49: TX-0044 | C49: DET001 | D49: =IFERROR(INDEX(Products!$B$6:$B$60,MATCH(C49,Products!$A$6:$A$60,0)),"") -> Detergent Powder 900g | E49: =IFERROR(INDEX(Products!$C$6:$C$60,MATCH(C49,Products!$A$6:$A$60,0)),"") -> Home Care | F49: Sales Return | G49: 1 | H49: Madam Ngozi Shop, Oshodi | J49: =IFERROR(IF(OR(F49="Sale",F49="Sales Return"),INDEX(Products!$G$6:$G$60,MATCH(C49,Products!$A$6:$A$60,0)),INDEX(Products!$F$6:$F$60,MATCH(C49,Products!$A$6:$A$60,0))),0) -> 16200 | K49: =G49*J49 -> 16200 | L49: Wrong variant delivered
A50: 46315 | B50: TX-0045 | C50: BEV001 | D50: =IFERROR(INDEX(Products!$B$6:$B$60,MATCH(C50,Products!$A$6:$A$60,0)),"") -> Cola Soft Drink 50cl PET | E50: =IFERROR(INDEX(Products!$C$6:$C$60,MATCH(C50,Products!$A$6:$A$60,0)),"") -> Beverages | F50: Sale | G50: 4 | H50: Balogun Market Stall 14, Lagos Island | I50: Cash | J50: =IFERROR(IF(OR(F50="Sale",F50="Sales Return"),INDEX(Products!$G$6:$G$60,MATCH(C50,Products!$A$6:$A$60,0)),INDEX(Products!$F$6:$F$60,MATCH(C50,Products!$A$6:$A$60,0))),0) -> 5900 | K50: =G50*J50 -> 23600
A51: 46315 | B51: TX-0046 | C51: BEV001 | D51: =IFERROR(INDEX(Products!$B$6:$B$60,MATCH(C51,Products!$A$6:$A$60,0)),"") -> Cola Soft Drink 50cl PET | E51: =IFERROR(INDEX(Products!$C$6:$C$60,MATCH(C51,Products!$A$6:$A$60,0)),"") -> Beverages | F51: Sale | G51: 2 | H51: Balogun Market Stall 14, Lagos Island | I51: Cash | J51: =IFERROR(IF(OR(F51="Sale",F51="Sales Return"),INDEX(Products!$G$6:$G$60,MATCH(C51,Products!$A$6:$A$60,0)),INDEX(Products!$F$6:$F$60,MATCH(C51,Products!$A$6:$A$60,0))),0) -> 5900 | K51: =G51*J51 -> 11800
A52: 46315 | B52: TX-0047 | C52: BEV002 | D52: =IFERROR(INDEX(Products!$B$6:$B$60,MATCH(C52,Products!$A$6:$A$60,0)),"") -> Orange Soft Drink 50cl PET | E52: =IFERROR(INDEX(Products!$C$6:$C$60,MATCH(C52,Products!$A$6:$A$60,0)),"") -> Beverages | F52: Sale | G52: 6 | H52: Ebenezer Provision Store, Ajegunle | I52: Credit | J52: =IFERROR(IF(OR(F52="Sale",F52="Sales Return"),INDEX(Products!$G$6:$G$60,MATCH(C52,Products!$A$6:$A$60,0)),INDEX(Products!$F$6:$F$60,MATCH(C52,Products!$A$6:$A$60,0))),0) -> 5900 | K52: =G52*J52 -> 35400
A53: 46315 | B53: TX-0048 | C53: BEV003 | D53: =IFERROR(INDEX(Products!$B$6:$B$60,MATCH(C53,Products!$A$6:$A$60,0)),"") -> Table Water 75cl | E53: =IFERROR(INDEX(Products!$C$6:$C$60,MATCH(C53,Products!$A$6:$A$60,0)),"") -> Beverages | F53: Sale | G53: 7 | H53: Mama Chidi Provisions, Mushin | I53: Cash | J53: =IFERROR(IF(OR(F53="Sale",F53="Sales Return"),INDEX(Products!$G$6:$G$60,MATCH(C53,Products!$A$6:$A$60,0)),INDEX(Products!$F$6:$F$60,MATCH(C53,Products!$A$6:$A$60,0))),0) -> 2300 | K53: =G53*J53 -> 16100
A54: 46315 | B54: TX-0049 | C54: BEV003 | D54: =IFERROR(INDEX(Products!$B$6:$B$60,MATCH(C54,Products!$A$6:$A$60,0)),"") -> Table Water 75cl | E54: =IFERROR(INDEX(Products!$C$6:$C$60,MATCH(C54,Products!$A$6:$A$60,0)),"") -> Beverages | F54: Sale | G54: 7 | H54: Oluwaseun Mini-Mart, Surulere | I54: Cash | J54: =IFERROR(IF(OR(F54="Sale",F54="Sales Return"),INDEX(Products!$G$6:$G$60,MATCH(C54,Products!$A$6:$A$60,0)),INDEX(Products!$F$6:$F$60,MATCH(C54,Products!$A$6:$A$60,0))),0) -> 2300 | K54: =G54*J54 -> 16100
A55: 46315 | B55: TX-0050 | C55: BEV004 | D55: =IFERROR(INDEX(Products!$B$6:$B$60,MATCH(C55,Products!$A$6:$A$60,0)),"") -> Malt Drink 33cl Can | E55: =IFERROR(INDEX(Products!$C$6:$C$60,MATCH(C55,Products!$A$6:$A$60,0)),"") -> Beverages | F55: Sale | G55: 2 | H55: Sunrise Supermarket, Yaba | I55: Credit | J55: =IFERROR(IF(OR(F55="Sale",F55="Sales Return"),INDEX(Products!$G$6:$G$60,MATCH(C55,Products!$A$6:$A$60,0)),INDEX(Products!$F$6:$F$60,MATCH(C55,Products!$A$6:$A$60,0))),0) -> 11200 | K55: =G55*J55 -> 22400
A56: 46315 | B56: TX-0051 | C56: DET001 | D56: =IFERROR(INDEX(Products!$B$6:$B$60,MATCH(C56,Products!$A$6:$A$60,0)),"") -> Detergent Powder 900g | E56: =IFERROR(INDEX(Products!$C$6:$C$60,MATCH(C56,Products!$A$6:$A$60,0)),"") -> Home Care | F56: Sale | G56: 2 | H56: Mama Chidi Provisions, Mushin | I56: Credit | J56: =IFERROR(IF(OR(F56="Sale",F56="Sales Return"),INDEX(Products!$G$6:$G$60,MATCH(C56,Products!$A$6:$A$60,0)),INDEX(Products!$F$6:$F$60,MATCH(C56,Products!$A$6:$A$60,0))),0) -> 16200 | K56: =G56*J56 -> 32400
A57: 46315 | B57: TX-0052 | C57: DET001 | D57: =IFERROR(INDEX(Products!$B$6:$B$60,MATCH(C57,Products!$A$6:$A$60,0)),"") -> Detergent Powder 900g | E57: =IFERROR(INDEX(Products!$C$6:$C$60,MATCH(C57,Products!$A$6:$A$60,0)),"") -> Home Care | F57: Sale | G57: 1 | H57: Ebenezer Provision Store, Ajegunle | I57: Credit | J57: =IFERROR(IF(OR(F57="Sale",F57="Sales Return"),INDEX(Products!$G$6:$G$60,MATCH(C57,Products!$A$6:$A$60,0)),INDEX(Products!$F$6:$F$60,MATCH(C57,Products!$A$6:$A$60,0))),0) -> 16200 | K57: =G57*J57 -> 16200
A58: 46315 | B58: TX-0053 | C58: DET002 | D58: =IFERROR(INDEX(Products!$B$6:$B$60,MATCH(C58,Products!$A$6:$A$60,0)),"") -> Detergent Powder 400g | E58: =IFERROR(INDEX(Products!$C$6:$C$60,MATCH(C58,Products!$A$6:$A$60,0)),"") -> Home Care | F58: Sale | G58: 1 | H58: Sunrise Supermarket, Yaba | I58: Credit | J58: =IFERROR(IF(OR(F58="Sale",F58="Sales Return"),INDEX(Products!$G$6:$G$60,MATCH(C58,Products!$A$6:$A$60,0)),INDEX(Products!$F$6:$F$60,MATCH(C58,Products!$A$6:$A$60,0))),0) -> 19000 | K58: =G58*J58 -> 19000
A59: 46315 | B59: TX-0054 | C59: FDS001 | D59: =IFERROR(INDEX(Products!$B$6:$B$60,MATCH(C59,Products!$A$6:$A$60,0)),"") -> Evaporated Milk 160g Tin | E59: =IFERROR(INDEX(Products!$C$6:$C$60,MATCH(C59,Products!$A$6:$A$60,0)),"") -> Packaged Food | F59: Sale | G59: 2 | H59: Madam Ngozi Shop, Oshodi | I59: Cash | J59: =IFERROR(IF(OR(F59="Sale",F59="Sales Return"),INDEX(Products!$G$6:$G$60,MATCH(C59,Products!$A$6:$A$60,0)),INDEX(Products!$F$6:$F$60,MATCH(C59,Products!$A$6:$A$60,0))),0) -> 31000 | K59: =G59*J59 -> 62000
A60: 46315 | B60: TX-0055 | C60: FDS002 | D60: =IFERROR(INDEX(Products!$B$6:$B$60,MATCH(C60,Products!$A$6:$A$60,0)),"") -> Tomato Paste 70g Sachet | E60: =IFERROR(INDEX(Products!$C$6:$C$60,MATCH(C60,Products!$A$6:$A$60,0)),"") -> Packaged Food | F60: Sale | G60: 1 | H60: Madam Ngozi Shop, Oshodi | I60: Transfer | J60: =IFERROR(IF(OR(F60="Sale",F60="Sales Return"),INDEX(Products!$G$6:$G$60,MATCH(C60,Products!$A$6:$A$60,0)),INDEX(Products!$F$6:$F$60,MATCH(C60,Products!$A$6:$A$60,0))),0) -> 17200 | K60: =G60*J60 -> 17200
A61: 46315 | B61: TX-0056 | C61: FDS002 | D61: =IFERROR(INDEX(Products!$B$6:$B$60,MATCH(C61,Products!$A$6:$A$60,0)),"") -> Tomato Paste 70g Sachet | E61: =IFERROR(INDEX(Products!$C$6:$C$60,MATCH(C61,Products!$A$6:$A$60,0)),"") -> Packaged Food | F61: Sale | G61: 4 | H61: Ebenezer Provision Store, Ajegunle | I61: Cash | J61: =IFERROR(IF(OR(F61="Sale",F61="Sales Return"),INDEX(Products!$G$6:$G$60,MATCH(C61,Products!$A$6:$A$60,0)),INDEX(Products!$F$6:$F$60,MATCH(C61,Products!$A$6:$A$60,0))),0) -> 17200 | K61: =G61*J61 -> 68800
...

Sheet Register
A1: Inventory Register
A2: Expected Closing = Opening + Stock Received + Sales Returns − Units Sold − Supplier Returns − Damaged. Blue cells: enter opening stock and physical count.
A3: ="Week: "&TEXT(Settings!B5,"dd mmm yyyy")&" to "&TEXT(Settings!B7,"dd mmm yyyy") -> Week: 19 Oct 2026 to 24 Oct 2026
A5: Product Code | B5: Product Name | C5: Supplier | D5: Opening Stock | E5: Stock Received (Purchases) | F5: Sales Returns | G5: Units Sold | H5: Supplier Returns | I5: Damaged Stock | J5: Expected Closing (Book) | K5: Physical Count | L5: Variance (units) | M5: Unit Cost (₦) | N5: Variance Value (₦) | O5: Variance % | P5: Count Status
A6: =Products!A6 -> BEV001 | B6: =Products!B6 -> Cola Soft Drink 50cl PET | C6: =Products!D6 -> Apapa Beverages Depot | D6: 31 | E6: =SUMIFS(Transactions!$G$6:$G$1000,Transactions!$C$6:$C$1000,$A6,Transactions!$F$6:$F$1000,"Purchase",Transactions!$A$6:$A$1000,">="&Settings!$B$5,Transactions!$A$6:$A$1000,"<="&Settings!$B$7) -> 54 | F6: =SUMIFS(Transactions!$G$6:$G$1000,Transactions!$C$6:$C$1000,$A6,Transactions!$F$6:$F$1000,"Sales Return",Transactions!$A$6:$A$1000,">="&Settings!$B$5,Transactions!$A$6:$A$1000,"<="&Settings!$B$7) -> 2 | G6: =SUMIFS(Transactions!$G$6:$G$1000,Transactions!$C$6:$C$1000,$A6,Transactions!$F$6:$F$1000,"Sale",Transactions!$A$6:$A$1000,">="&Settings!$B$5,Transactions!$A$6:$A$1000,"<="&Settings!$B$7) -> 60 | H6: =SUMIFS(Transactions!$G$6:$G$1000,Transactions!$C$6:$C$1000,$A6,Transactions!$F$6:$F$1000,"Supplier Return",Transactions!$A$6:$A$1000,">="&Settings!$B$5,Transactions!$A$6:$A$1000,"<="&Settings!$B$7) -> 0 | I6: =SUMIFS(Transactions!$G$6:$G$1000,Transactions!$C$6:$C$1000,$A6,Transactions!$F$6:$F$1000,"Damaged",Transactions!$A$6:$A$1000,">="&Settings!$B$5,Transactions!$A$6:$A$1000,"<="&Settings!$B$7) -> 0 | J6: =D6+E6+F6-G6-H6-I6 -> 27 | K6: 25 | L6: =IF(K6="","",K6-J6) -> -2 | M6: =Products!F6 -> 5200 | N6: =IF(L6="","",L6*M6) -> -10400 | O6: =IF(OR(K6="",J6<=0),"",L6/J6) -> -0.074074074 | P6: =IF(K6="","Not counted",IF(L6=0,"Match",IF(L6<0,"Shortage","Overage"))) -> Shortage
A7: =Products!A7 -> BEV002 | B7: =Products!B7 -> Orange Soft Drink 50cl PET | C7: =Products!D7 -> Apapa Beverages Depot | D7: 32 | E7: =SUMIFS(Transactions!$G$6:$G$1000,Transactions!$C$6:$C$1000,$A7,Transactions!$F$6:$F$1000,"Purchase",Transactions!$A$6:$A$1000,">="&Settings!$B$5,Transactions!$A$6:$A$1000,"<="&Settings!$B$7) -> 36 | F7: =SUMIFS(Transactions!$G$6:$G$1000,Transactions!$C$6:$C$1000,$A7,Transactions!$F$6:$F$1000,"Sales Return",Transactions!$A$6:$A$1000,">="&Settings!$B$5,Transactions!$A$6:$A$1000,"<="&Settings!$B$7) -> 0 | G7: =SUMIFS(Transactions!$G$6:$G$1000,Transactions!$C$6:$C$1000,$A7,Transactions!$F$6:$F$1000,"Sale",Transactions!$A$6:$A$1000,">="&Settings!$B$5,Transactions!$A$6:$A$1000,"<="&Settings!$B$7) -> 42 | H7: =SUMIFS(Transactions!$G$6:$G$1000,Transactions!$C$6:$C$1000,$A7,Transactions!$F$6:$F$1000,"Supplier Return",Transactions!$A$6:$A$1000,">="&Settings!$B$5,Transactions!$A$6:$A$1000,"<="&Settings!$B$7) -> 0 | I7: =SUMIFS(Transactions!$G$6:$G$1000,Transactions!$C$6:$C$1000,$A7,Transactions!$F$6:$F$1000,"Damaged",Transactions!$A$6:$A$1000,">="&Settings!$B$5,Transactions!$A$6:$A$1000,"<="&Settings!$B$7) -> 1 | J7: =D7+E7+F7-G7-H7-I7 -> 25 | K7: 25 | L7: =IF(K7="","",K7-J7) -> 0 | M7: =Products!F7 -> 5200 | N7: =IF(L7="","",L7*M7) -> 0 | O7: =IF(OR(K7="",J7<=0),"",L7/J7) -> 0 | P7: =IF(K7="","Not counted",IF(L7=0,"Match",IF(L7<0,"Shortage","Overage"))) -> Match
A8: =Products!A8 -> BEV003 | B8: =Products!B8 -> Table Water 75cl | C8: =Products!D8 -> Apapa Beverages Depot | D8: 64 | E8: =SUMIFS(Transactions!$G$6:$G$1000,Transactions!$C$6:$C$1000,$A8,Transactions!$F$6:$F$1000,"Purchase",Transactions!$A$6:$A$1000,">="&Settings!$B$5,Transactions!$A$6:$A$1000,"<="&Settings!$B$7) -> 66 | F8: =SUMIFS(Transactions!$G$6:$G$1000,Transactions!$C$6:$C$1000,$A8,Transactions!$F$6:$F$1000,"Sales Return",Transactions!$A$6:$A$1000,">="&Settings!$B$5,Transactions!$A$6:$A$1000,"<="&Settings!$B$7) -> 2 | G8: =SUMIFS(Transactions!$G$6:$G$1000,Transactions!$C$6:$C$1000,$A8,Transactions!$F$6:$F$1000,"Sale",Transactions!$A$6:$A$1000,">="&Settings!$B$5,Transactions!$A$6:$A$1000,"<="&Settings!$B$7) -> 72 | H8: =SUMIFS(Transactions!$G$6:$G$1000,Transactions!$C$6:$C$1000,$A8,Transactions!$F$6:$F$1000,"Supplier Return",Transactions!$A$6:$A$1000,">="&Settings!$B$5,Transactions!$A$6:$A$1000,"<="&Settings!$B$7) -> 0 | I8: =SUMIFS(Transactions!$G$6:$G$1000,Transactions!$C$6:$C$1000,$A8,Transactions!$F$6:$F$1000,"Damaged",Transactions!$A$6:$A$1000,">="&Settings!$B$5,Transactions!$A$6:$A$1000,"<="&Settings!$B$7) -> 1 | J8: =D8+E8+F8-G8-H8-I8 -> 59 | K8: 55 | L8: =IF(K8="","",K8-J8) -> -4 | M8: =Products!F8 -> 1900 | N8: =IF(L8="","",L8*M8) -> -7600 | O8: =IF(OR(K8="",J8<=0),"",L8/J8) -> -0.06779661 | P8: =IF(K8="","Not counted",IF(L8=0,"Match",IF(L8<0,"Shortage","Overage"))) -> Shortage
A9: =Products!A9 -> BEV004 | B9: =Products!B9 -> Malt Drink 33cl Can | C9: =Products!D9 -> Apapa Beverages Depot | D9: 37 | E9: =SUMIFS(Transactions!$G$6:$G$1000,Transactions!$C$6:$C$1000,$A9,Transactions!$F$6:$F$1000,"Purchase",Transactions!$A$6:$A$1000,">="&Settings!$B$5,Transactions!$A$6:$A$1000,"<="&Settings!$B$7) -> 0 | F9: =SUMIFS(Transactions!$G$6:$G$1000,Transactions!$C$6:$C$1000,$A9,Transactions!$F$6:$F$1000,"Sales Return",Transactions!$A$6:$A$1000,">="&Settings!$B$5,Transactions!$A$6:$A$1000,"<="&Settings!$B$7) -> 0 | G9: =SUMIFS(Transactions!$G$6:$G$1000,Transactions!$C$6:$C$1000,$A9,Transactions!$F$6:$F$1000,"Sale",Transactions!$A$6:$A$1000,">="&Settings!$B$5,Transactions!$A$6:$A$1000,"<="&Settings!$B$7) -> 9 | H9: =SUMIFS(Transactions!$G$6:$G$1000,Transactions!$C$6:$C$1000,$A9,Transactions!$F$6:$F$1000,"Supplier Return",Transactions!$A$6:$A$1000,">="&Settings!$B$5,Transactions!$A$6:$A$1000,"<="&Settings!$B$7) -> 1 | I9: =SUMIFS(Transactions!$G$6:$G$1000,Transactions!$C$6:$C$1000,$A9,Transactions!$F$6:$F$1000,"Damaged",Transactions!$A$6:$A$1000,">="&Settings!$B$5,Transactions!$A$6:$A$1000,"<="&Settings!$B$7) -> 0 | J9: =D9+E9+F9-G9-H9-I9 -> 27 | K9: 27 | L9: =IF(K9="","",K9-J9) -> 0 | M9: =Products!F9 -> 9800 | N9: =IF(L9="","",L9*M9) -> 0 | O9: =IF(OR(K9="",J9<=0),"",L9/J9) -> 0 | P9: =IF(K9="","Not counted",IF(L9=0,"Match",IF(L9<0,"Shortage","Overage"))) -> Match
A10: =Products!A10 -> NDL001 | B10: =Products!B10 -> Instant Noodles Chicken 70g | C10: =Products!D10 -> Mushin Noodles & Foods Ltd | D10: 118 | E10: =SUMIFS(Transactions!$G$6:$G$1000,Transactions!$C$6:$C$1000,$A10,Transactions!$F$6:$F$1000,"Purchase",Transactions!$A$6:$A$1000,">="&Settings!$B$5,Transactions!$A$6:$A$1000,"<="&Settings!$B$7) -> 80 | F10: =SUMIFS(Transactions!$G$6:$G$1000,Transactions!$C$6:$C$1000,$A10,Transactions!$F$6:$F$1000,"Sales Return",Transactions!$A$6:$A$1000,">="&Settings!$B$5,Transactions!$A$6:$A$1000,"<="&Settings!$B$7) -> 2 | G10: =SUMIFS(Transactions!$G$6:$G$1000,Transactions!$C$6:$C$1000,$A10,Transactions!$F$6:$F$1000,"Sale",Transactions!$A$6:$A$1000,">="&Settings!$B$5,Transactions!$A$6:$A$1000,"<="&Settings!$B$7) -> 90 | H10: =SUMIFS(Transactions!$G$6:$G$1000,Transactions!$C$6:$C$1000,$A10,Transactions!$F$6:$F$1000,"Supplier Return",Transactions!$A$6:$A$1000,">="&Settings!$B$5,Transactions!$A$6:$A$1000,"<="&Settings!$B$7) -> 0 | I10: =SUMIFS(Transactions!$G$6:$G$1000,Transactions!$C$6:$C$1000,$A10,Transactions!$F$6:$F$1000,"Damaged",Transactions!$A$6:$A$1000,">="&Settings!$B$5,Transactions!$A$6:$A$1000,"<="&Settings!$B$7) -> 2 | J10: =D10+E10+F10-G10-H10-I10 -> 108 | K10: 105 | L10: =IF(K10="","",K10-J10) -> -3 | M10: =Products!F10 -> 7600 | N10: =IF(L10="","",L10*M10) -> -22800 | O10: =IF(OR(K10="",J10<=0),"",L10/J10) -> -0.027777778 | P10: =IF(K10="","Not counted",IF(L10=0,"Match",IF(L10<0,"Shortage","Overage"))) -> Shortage
A11: =Products!A11 -> NDL002 | B11: =Products!B11 -> Instant Noodles Onion 70g | C11: =Products!D11 -> Mushin Noodles & Foods Ltd | D11: 27 | E11: =SUMIFS(Transactions!$G$6:$G$1000,Transactions!$C$6:$C$1000,$A11,Transactions!$F$6:$F$1000,"Purchase",Transactions!$A$6:$A$1000,">="&Settings!$B$5,Transactions!$A$6:$A$1000,"<="&Settings!$B$7) -> 29 | F11: =SUMIFS(Transactions!$G$6:$G$1000,Transactions!$C$6:$C$1000,$A11,Transactions!$F$6:$F$1000,"Sales Return",Transactions!$A$6:$A$1000,">="&Settings!$B$5,Transactions!$A$6:$A$1000,"<="&Settings!$B$7) -> 0 | G11: =SUMIFS(Transactions!$G$6:$G$1000,Transactions!$C$6:$C$1000,$A11,Transactions!$F$6:$F$1000,"Sale",Transactions!$A$6:$A$1000,">="&Settings!$B$5,Transactions!$A$6:$A$1000,"<="&Settings!$B$7) -> 54 | H11: =SUMIFS(Transactions!$G$6:$G$1000,Transactions!$C$6:$C$1000,$A11,Transactions!$F$6:$F$1000,"Supplier Return",Transactions!$A$6:$A$1000,">="&Settings!$B$5,Transactions!$A$6:$A$1000,"<="&Settings!$B$7) -> 2 | I11: =SUMIFS(Transactions!$G$6:$G$1000,Transactions!$C$6:$C$1000,$A11,Transactions!$F$6:$F$1000,"Damaged",Transactions!$A$6:$A$1000,">="&Settings!$B$5,Transactions!$A$6:$A$1000,"<="&Settings!$B$7) -> 0 | J11: =D11+E11+F11-G11-H11-I11 -> 0 | K11: 0 | L11: =IF(K11="","",K11-J11) -> 0 | M11: =Products!F11 -> 7700 | N11: =IF(L11="","",L11*M11) -> 0 | O11: =IF(OR(K11="",J11<=0),"",L11/J11) | P11: =IF(K11="","Not counted",IF(L11=0,"Match",IF(L11<0,"Shortage","Overage"))) -> Match
A12: =Products!A12 -> NDL003 | B12: =Products!B12 -> Spaghetti 500g | C12: =Products!D12 -> Mushin Noodles & Foods Ltd | D12: 35 | E12: =SUMIFS(Transactions!$G$6:$G$1000,Transactions!$C$6:$C$1000,$A12,Transactions!$F$6:$F$1000,"Purchase",Transactions!$A$6:$A$1000,">="&Settings!$B$5,Transactions!$A$6:$A$1000,"<="&Settings!$B$7) -> 0 | F12: =SUMIFS(Transactions!$G$6:$G$1000,Transactions!$C$6:$C$1000,$A12,Transactions!$F$6:$F$1000,"Sales Return",Transactions!$A$6:$A$1000,">="&Settings!$B$5,Transactions!$A$6:$A$1000,"<="&Settings!$B$7) -> 0 | G12: =SUMIFS(Transactions!$G$6:$G$1000,Transactions!$C$6:$C$1000,$A12,Transactions!$F$6:$F$1000,"Sale",Transactions!$A$6:$A$1000,">="&Settings!$B$5,Transactions!$A$6:$A$1000,"<="&Settings!$B$7) -> 12 | H12: =SUMIFS(Transactions!$G$6:$G$1000,Transactions!$C$6:$C$1000,$A12,Transactions!$F$6:$F$1000,"Supplier Return",Transactions!$A$6:$A$1000,">="&Settings!$B$5,Transactions!$A$6:$A$1000,"<="&Settings!$B$7) -> 0 | I12: =SUMIFS(Transactions!$G$6:$G$1000,Transactions!$C$6:$C$1000,$A12,Transactions!$F$6:$F$1000,"Damaged",Transactions!$A$6:$A$1000,">="&Settings!$B$5,Transactions!$A$6:$A$1000,"<="&Settings!$B$7) -> 0 | J12: =D12+E12+F12-G12-H12-I12 -> 23 | K12: 24 | L12: =IF(K12="","",K12-J12) -> 1 | M12: =Products!F12 -> 11500 | N12: =IF(L12="","",L12*M12) -> 11500 | O12: =IF(OR(K12="",J12<=0),"",L12/J12) -> 0.043478261 | P12: =IF(K12="","Not counted",IF(L12=0,"Match",IF(L12<0,"Shortage","Overage"))) -> Overage
A13: =Products!A13 -> OIL001 | B13: =Products!B13 -> Vegetable Oil 5L | C13: =Products!D13 -> Ikorodu Oil Mills (Agent) | D13: 23 | E13: =SUMIFS(Transactions!$G$6:$G$1000,Transactions!$C$6:$C$1000,$A13,Transactions!$F$6:$F$1000,"Purchase",Transactions!$A$6:$A$1000,">="&Settings!$B$5,Transactions!$A$6:$A$1000,"<="&Settings!$B$7) -> 22 | F13: =SUMIFS(Transactions!$G$6:$G$1000,Transactions!$C$6:$C$1000,$A13,Transactions!$F$6:$F$1000,"Sales Return",Transactions!$A$6:$A$1000,">="&Settings!$B$5,Transactions!$A$6:$A$1000,"<="&Settings!$B$7) -> 1 | G13: =SUMIFS(Transactions!$G$6:$G$1000,Transactions!$C$6:$C$1000,$A13,Transactions!$F$6:$F$1000,"Sale",Transactions!$A$6:$A$1000,">="&Settings!$B$5,Transactions!$A$6:$A$1000,"<="&Settings!$B$7) -> 24 | H13: =SUMIFS(Transactions!$G$6:$G$1000,Transactions!$C$6:$C$1000,$A13,Transactions!$F$6:$F$1000,"Supplier Return",Transactions!$A$6:$A$1000,">="&Settings!$B$5,Transactions!$A$6:$A$1000,"<="&Settings!$B$7) -> 0 | I13: =SUMIFS(Transactions!$G$6:$G$1000,Transactions!$C$6:$C$1000,$A13,Transactions!$F$6:$F$1000,"Damaged",Transactions!$A$6:$A$1000,">="&Settings!$B$5,Transactions!$A$6:$A$1000,"<="&Settings!$B$7) -> 0 | J13: =D13+E13+F13-G13-H13-I13 -> 22 | K13: 21 | L13: =IF(K13="","",K13-J13) -> -1 | M13: =Products!F13 -> 38000 | N13: =IF(L13="","",L13*M13) -> -38000 | O13: =IF(OR(K13="",J13<=0),"",L13/J13) -> -0.045454545 | P13: =IF(K13="","Not counted",IF(L13=0,"Match",IF(L13<0,"Shortage","Overage"))) -> Shortage
A14: =Products!A14 -> OIL002 | B14: =Products!B14 -> Vegetable Oil 1L | C14: =Products!D14 -> Ikorodu Oil Mills (Agent) | D14: 28 | E14: =SUMIFS(Transactions!$G$6:$G$1000,Transactions!$C$6:$C$1000,$A14,Transactions!$F$6:$F$1000,"Purchase",Transactions!$A$6:$A$1000,">="&Settings!$B$5,Transactions!$A$6:$A$1000,"<="&Settings!$B$7) -> 0 | F14: =SUMIFS(Transactions!$G$6:$G$1000,Transactions!$C$6:$C$1000,$A14,Transactions!$F$6:$F$1000,"Sales Return",Transactions!$A$6:$A$1000,">="&Settings!$B$5,Transactions!$A$6:$A$1000,"<="&Settings!$B$7) -> 0 | G14: =SUMIFS(Transactions!$G$6:$G$1000,Transactions!$C$6:$C$1000,$A14,Transactions!$F$6:$F$1000,"Sale",Transactions!$A$6:$A$1000,">="&Settings!$B$5,Transactions!$A$6:$A$1000,"<="&Settings!$B$7) -> 10 | H14: =SUMIFS(Transactions!$G$6:$G$1000,Transactions!$C$6:$C$1000,$A14,Transactions!$F$6:$F$1000,"Supplier Return",Transactions!$A$6:$A$1000,">="&Settings!$B$5,Transactions!$A$6:$A$1000,"<="&Settings!$B$7) -> 0 | I14: =SUMIFS(Transactions!$G$6:$G$1000,Transactions!$C$6:$C$1000,$A14,Transactions!$F$6:$F$1000,"Damaged",Transactions!$A$6:$A$1000,">="&Settings!$B$5,Transactions!$A$6:$A$1000,"<="&Settings!$B$7) -> 1 | J14: =D14+E14+F14-G14-H14-I14 -> 17 | K14: 17 | L14: =IF(K14="","",K14-J14) -> 0 | M14: =Products!F14 -> 36000 | N14: =IF(L14="","",L14*M14) -> 0 | O14: =IF(OR(K14="",J14<=0),"",L14/J14) -> 0 | P14: =IF(K14="","Not counted",IF(L14=0,"Match",IF(L14<0,"Shortage","Overage"))) -> Match
A15: =Products!A15 -> DET001 | B15: =Products!B15 -> Detergent Powder 900g | C15: =Products!D15 -> Oshodi Home Care Supplies | D15: 31 | E15: =SUMIFS(Transactions!$G$6:$G$1000,Transactions!$C$6:$C$1000,$A15,Transactions!$F$6:$F$1000,"Purchase",Transactions!$A$6:$A$1000,">="&Settings!$B$5,Transactions!$A$6:$A$1000,"<="&Settings!$B$7) -> 24 | F15: =SUMIFS(Transactions!$G$6:$G$1000,Transactions!$C$6:$C$1000,$A15,Transactions!$F$6:$F$1000,"Sales Return",Transactions!$A$6:$A$1000,">="&Settings!$B$5,Transactions!$A$6:$A$1000,"<="&Settings!$B$7) -> 1 | G15: =SUMIFS(Transactions!$G$6:$G$1000,Transactions!$C$6:$C$1000,$A15,Transactions!$F$6:$F$1000,"Sale",Transactions!$A$6:$A$1000,">="&Settings!$B$5,Transactions!$A$6:$A$1000,"<="&Settings!$B$7) -> 30 | H15: =SUMIFS(Transactions!$G$6:$G$1000,Transactions!$C$6:$C$1000,$A15,Transactions!$F$6:$F$1000,"Supplier Return",Transactions!$A$6:$A$1000,">="&Settings!$B$5,Transactions!$A$6:$A$1000,"<="&Settings!$B$7) -> 0 | I15: =SUMIFS(Transactions!$G$6:$G$1000,Transactions!$C$6:$C$1000,$A15,Transactions!$F$6:$F$1000,"Damaged",Transactions!$A$6:$A$1000,">="&Settings!$B$5,Transactions!$A$6:$A$1000,"<="&Settings!$B$7) -> 0 | J15: =D15+E15+F15-G15-H15-I15 -> 26 | K15: 27 | L15: =IF(K15="","",K15-J15) -> 1 | M15: =Products!F15 -> 14400 | N15: =IF(L15="","",L15*M15) -> 14400 | O15: =IF(OR(K15="",J15<=0),"",L15/J15) -> 0.038461538 | P15: =IF(K15="","Not counted",IF(L15=0,"Match",IF(L15<0,"Shortage","Overage"))) -> Overage
A16: =Products!A16 -> DET002 | B16: =Products!B16 -> Detergent Powder 400g | C16: =Products!D16 -> Oshodi Home Care Supplies | D16: 51 | E16: =SUMIFS(Transactions!$G$6:$G$1000,Transactions!$C$6:$C$1000,$A16,Transactions!$F$6:$F$1000,"Purchase",Transactions!$A$6:$A$1000,">="&Settings!$B$5,Transactions!$A$6:$A$1000,"<="&Settings!$B$7) -> 0 | F16: =SUMIFS(Transactions!$G$6:$G$1000,Transactions!$C$6:$C$1000,$A16,Transactions!$F$6:$F$1000,"Sales Return",Transactions!$A$6:$A$1000,">="&Settings!$B$5,Transactions!$A$6:$A$1000,"<="&Settings!$B$7) -> 0 | G16: =SUMIFS(Transactions!$G$6:$G$1000,Transactions!$C$6:$C$1000,$A16,Transactions!$F$6:$F$1000,"Sale",Transactions!$A$6:$A$1000,">="&Settings!$B$5,Transactions!$A$6:$A$1000,"<="&Settings!$B$7) -> 20 | H16: =SUMIFS(Transactions!$G$6:$G$1000,Transactions!$C$6:$C$1000,$A16,Transactions!$F$6:$F$1000,"Supplier Return",Transactions!$A$6:$A$1000,">="&Settings!$B$5,Transactions!$A$6:$A$1000,"<="&Settings!$B$7) -> 0 | I16: =SUMIFS(Transactions!$G$6:$G$1000,Transactions!$C$6:$C$1000,$A16,Transactions!$F$6:$F$1000,"Damaged",Transactions!$A$6:$A$1000,">="&Settings!$B$5,Transactions!$A$6:$A$1000,"<="&Settings!$B$7) -> 1 | J16: =D16+E16+F16-G16-H16-I16 -> 30 | K16: 30 | L16: =IF(K16="","",K16-J16) -> 0 | M16: =Products!F16 -> 17000 | N16: =IF(L16="","",L16*M16) -> 0 | O16: =IF(OR(K16="",J16<=0),"",L16/J16) -> 0 | P16: =IF(K16="","Not counted",IF(L16=0,"Match",IF(L16<0,"Shortage","Overage"))) -> Match
A17: =Products!A17 -> DET003 | B17: =Products!B17 -> Laundry Bar Soap | C17: =Products!D17 -> Oshodi Home Care Supplies | D17: 35 | E17: =SUMIFS(Transactions!$G$6:$G$1000,Transactions!$C$6:$C$1000,$A17,Transactions!$F$6:$F$1000,"Purchase",Transactions!$A$6:$A$1000,">="&Settings!$B$5,Transactions!$A$6:$A$1000,"<="&Settings!$B$7) -> 0 | F17: =SUMIFS(Transactions!$G$6:$G$1000,Transactions!$C$6:$C$1000,$A17,Transactions!$F$6:$F$1000,"Sales Return",Transactions!$A$6:$A$1000,">="&Settings!$B$5,Transactions!$A$6:$A$1000,"<="&Settings!$B$7) -> 0 | G17: =SUMIFS(Transactions!$G$6:$G$1000,Transactions!$C$6:$C$1000,$A17,Transactions!$F$6:$F$1000,"Sale",Transactions!$A$6:$A$1000,">="&Settings!$B$5,Transactions!$A$6:$A$1000,"<="&Settings!$B$7) -> 7 | H17: =SUMIFS(Transactions!$G$6:$G$1000,Transactions!$C$6:$C$1000,$A17,Transactions!$F$6:$F$1000,"Supplier Return",Transactions!$A$6:$A$1000,">="&Settings!$B$5,Transactions!$A$6:$A$1000,"<="&Settings!$B$7) -> 0 | I17: =SUMIFS(Transactions!$G$6:$G$1000,Transactions!$C$6:$C$1000,$A17,Transactions!$F$6:$F$1000,"Damaged",Transactions!$A$6:$A$1000,">="&Settings!$B$5,Transactions!$A$6:$A$1000,"<="&Settings!$B$7) -> 0 | J17: =D17+E17+F17-G17-H17-I17 -> 28 | K17: 28 | L17: =IF(K17="","",K17-J17) -> 0 | M17: =Products!F17 -> 9000 | N17: =IF(L17="","",L17*M17) -> 0 | O17: =IF(OR(K17="",J17<=0),"",L17/J17) -> 0 | P17: =IF(K17="","Not counted",IF(L17=0,"Match",IF(L17<0,"Shortage","Overage"))) -> Match
... A23: =Products!A23 -> FDS006 | B23: =Products!B23 -> Cocoa Beverage Powder 400g | C23: =Products!D23 -> Idumota Dry Goods Traders | D23: 32 | E23: =SUMIFS(Transactions!$G$6:$G$1000,Transactions!$C$6:$C$1000,$A23,Transactions!$F$6:$F$1000,"Purchase",Transactions!$A$6:$A$1000,">="&Settings!$B$5,Transactions!$A$6:$A$1000,"<="&Settings!$B$7) -> 0 | F23: =SUMIFS(Transactions!$G$6:$G$1000,Transactions!$C$6:$C$1000,$A23,Transactions!$F$6:$F$1000,"Sales Return",Transactions!$A$6:$A$1000,">="&Settings!$B$5,Transactions!$A$6:$A$1000,"<="&Settings!$B$7) -> 0 | G23: =SUMIFS(Transactions!$G$6:$G$1000,Transactions!$C$6:$C$1000,$A23,Transactions!$F$6:$F$1000,"Sale",Transactions!$A$6:$A$1000,">="&Settings!$B$5,Transactions!$A$6:$A$1000,"<="&Settings!$B$7) -> 6 | H23: =SUMIFS(Transactions!$G$6:$G$1000,Transactions!$C$6:$C$1000,$A23,Transactions!$F$6:$F$1000,"Supplier Return",Transactions!$A$6:$A$1000,">="&Settings!$B$5,Transactions!$A$6:$A$1000,"<="&Settings!$B$7) -> 0 | I23: =SUMIFS(Transactions!$G$6:$G$1000,Transactions!$C$6:$C$1000,$A23,Transactions!$F$6:$F$1000,"Damaged",Transactions!$A$6:$A$1000,">="&Settings!$B$5,Transactions!$A$6:$A$1000,"<="&Settings!$B$7) -> 0 | J23: =D23+E23+F23-G23-H23-I23 -> 26 | K23: 26 | L23: =IF(K23="","",K23-J23) -> 0 | M23: =Products!F23 -> 21000 | N23: =IF(L23="","",L23*M23) -> 0 | O23: =IF(OR(K23="",J23<=0),"",L23/J23) -> 0 | P23: =IF(K23="","Not counted",IF(L23=0,"Match",IF(L23<0,"Shortage","Overage"))) -> Match
A24: TOTAL | D24: =SUM(D6:D23) -> 784 | E24: =SUM(E6:E23) -> 345 | F24: =SUM(F6:F23) -> 10 | G24: =SUM(G6:G23) -> 532 | H24: =SUM(H6:H23) -> 4 | I24: =SUM(I6:I23) -> 9 | J24: =SUM(J6:J23) -> 594 | K24: =SUM(K6:K23) -> 584 | L24: =SUM(L6:L23) -> -10 | N24: =SUM(N6:N23) -> -86900

Sheet Reorder Dashboard
A1: Reorder Alert Dashboard
A2: Stock on hand uses the physical count where entered. Minimum = average daily sales × (lead time + safety days). Blue Override cells let you set your own minimum.
A4: STOCK-OUT | B4: REORDER NOW | C4: APPROACHING | D4: OK | E4: Est. reorder value (₦)
A5: =COUNTIF($K$9:$K$26,"STOCK-OUT") -> 1 | B5: =COUNTIF($K$9:$K$26,"REORDER NOW") -> 4 | C5: =COUNTIF($K$9:$K$26,"APPROACHING") -> 3 | D5: =COUNTIF($K$9:$K$26,"OK") -> 10 | E5: =SUM(N9:N26) -> 3977800
A8: Product Code | B8: Product Name | C8: Supplier | D8: Lead Time (days) | E8: Stock on Hand | F8: Avg Daily Sales | G8: Days of Cover | H8: Calculated Minimum | I8: Minimum Override | J8: Effective Minimum | K8: Alert | L8: Suggested Order Qty | M8: Unit Cost (₦) | N8: Est. Order Value (₦) | O8: Stock Level Bar
A9: =Products!A6 -> BEV001 | B9: =Products!B6 -> Cola Soft Drink 50cl PET | C9: =Products!D6 -> Apapa Beverages Depot | D9: =Products!H6 -> 2 | E9: =IF(Register!K6="",Register!J6,Register!K6) -> 25 | F9: =Register!G6/Settings!$B$6 -> 10 | G9: =IF(F9=0,"n/a",E9/F9) -> 2.5 | H9: =ROUNDUP(F9*(D9+Settings!$B$8),0) -> 40 | J9: =IF(I9="",H9,I9) -> 40 | K9: =IF(E9<=0,"STOCK-OUT",IF(E9<=J9,"REORDER NOW",IF(E9<=J9*(1+Settings!$B$10),"APPROACHING","OK"))) -> REORDER NOW | L9: =IF(OR(K9="STOCK-OUT",K9="REORDER NOW"),MAX(0,ROUNDUP(F9*Settings!$B$9-E9,0)),0) -> 115 | M9: =Products!F6 -> 5200 | N9: =L9*M9 -> 598000 | O9: =IF(K9="STOCK-OUT",REPT("█",3),IF(K9="REORDER NOW",REPT("█",6),IF(K9="APPROACHING",REPT("█",9),REPT("█",12)))) -> ██████
A10: =Products!A7 -> BEV002 | B10: =Products!B7 -> Orange Soft Drink 50cl PET | C10: =Products!D7 -> Apapa Beverages Depot | D10: =Products!H7 -> 2 | E10: =IF(Register!K7="",Register!J7,Register!K7) -> 25 | F10: =Register!G7/Settings!$B$6 -> 7 | G10: =IF(F10=0,"n/a",E10/F10) -> 3.5714286 | H10: =ROUNDUP(F10*(D10+Settings!$B$8),0) -> 28 | J10: =IF(I10="",H10,I10) -> 28 | K10: =IF(E10<=0,"STOCK-OUT",IF(E10<=J10,"REORDER NOW",IF(E10<=J10*(1+Settings!$B$10),"APPROACHING","OK"))) -> REORDER NOW | L10: =IF(OR(K10="STOCK-OUT",K10="REORDER NOW"),MAX(0,ROUNDUP(F10*Settings!$B$9-E10,0)),0) -> 73 | M10: =Products!F7 -> 5200 | N10: =L10*M10 -> 379600 | O10: =IF(K10="STOCK-OUT",REPT("█",3),IF(K10="REORDER NOW",REPT("█",6),IF(K10="APPROACHING",REPT("█",9),REPT("█",12)))) -> ██████
A11: =Products!A8 -> BEV003 | B11: =Products!B8 -> Table Water 75cl | C11: =Products!D8 -> Apapa Beverages Depot | D11: =Products!H8 -> 2 | E11: =IF(Register!K8="",Register!J8,Register!K8) -> 55 | F11: =Register!G8/Settings!$B$6 -> 12 | G11: =IF(F11=0,"n/a",E11/F11) -> 4.5833333 | H11: =ROUNDUP(F11*(D11+Settings!$B$8),0) -> 48 | J11: =IF(I11="",H11,I11) -> 48 | K11: =IF(E11<=0,"STOCK-OUT",IF(E11<=J11,"REORDER NOW",IF(E11<=J11*(1+Settings!$B$10),"APPROACHING","OK"))) -> APPROACHING | L11: =IF(OR(K11="STOCK-OUT",K11="REORDER NOW"),MAX(0,ROUNDUP(F11*Settings!$B$9-E11,0)),0) -> 0 | M11: =Products!F8 -> 1900 | N11: =L11*M11 -> 0 | O11: =IF(K11="STOCK-OUT",REPT("█",3),IF(K11="REORDER NOW",REPT("█",6),IF(K11="APPROACHING",REPT("█",9),REPT("█",12)))) -> █████████
A12: =Products!A9 -> BEV004 | B12: =Products!B9 -> Malt Drink 33cl Can | C12: =Products!D9 -> Apapa Beverages Depot | D12: =Products!H9 -> 2 | E12: =IF(Register!K9="",Register!J9,Register!K9) -> 27 | F12: =Register!G9/Settings!$B$6 -> 1.5 | G12: =IF(F12=0,"n/a",E12/F12) -> 18 | H12: =ROUNDUP(F12*(D12+Settings!$B$8),0) -> 6 | J12: =IF(I12="",H12,I12) -> 6 | K12: =IF(E12<=0,"STOCK-OUT",IF(E12<=J12,"REORDER NOW",IF(E12<=J12*(1+Settings!$B$10),"APPROACHING","OK"))) -> OK | L12: =IF(OR(K12="STOCK-OUT",K12="REORDER NOW"),MAX(0,ROUNDUP(F12*Settings!$B$9-E12,0)),0) -> 0 | M12: =Products!F9 -> 9800 | N12: =L12*M12 -> 0 | O12: =IF(K12="STOCK-OUT",REPT("█",3),IF(K12="REORDER NOW",REPT("█",6),IF(K12="APPROACHING",REPT("█",9),REPT("█",12)))) -> ████████████
A13: =Products!A10 -> NDL001 | B13: =Products!B10 -> Instant Noodles Chicken 70g | C13: =Products!D10 -> Mushin Noodles & Foods Ltd | D13: =Products!H10 -> 3 | E13: =IF(Register!K10="",Register!J10,Register!K10) -> 105 | F13: =Register!G10/Settings!$B$6 -> 15 | G13: =IF(F13=0,"n/a",E13/F13) -> 7 | H13: =ROUNDUP(F13*(D13+Settings!$B$8),0) -> 75 | J13: =IF(I13="",H13,I13) -> 75 | K13: =IF(E13<=0,"STOCK-OUT",IF(E13<=J13,"REORDER NOW",IF(E13<=J13*(1+Settings!$B$10),"APPROACHING","OK"))) -> OK | L13: =IF(OR(K13="STOCK-OUT",K13="REORDER NOW"),MAX(0,ROUNDUP(F13*Settings!$B$9-E13,0)),0) -> 0 | M13: =Products!F10 -> 7600 | N13: =L13*M13 -> 0 | O13: =IF(K13="STOCK-OUT",REPT("█",3),IF(K13="REORDER NOW",REPT("█",6),IF(K13="APPROACHING",REPT("█",9),REPT("█",12)))) -> ████████████
A14: =Products!A11 -> NDL002 | B14: =Products!B11 -> Instant Noodles Onion 70g | C14: =Products!D11 -> Mushin Noodles & Foods Ltd | D14: =Products!H11 -> 3 | E14: =IF(Register!K11="",Register!J11,Register!K11) -> 0 | F14: =Register!G11/Settings!$B$6 -> 9 | G14: =IF(F14=0,"n/a",E14/F14) -> 0 | H14: =ROUNDUP(F14*(D14+Settings!$B$8),0) -> 45 | J14: =IF(I14="",H14,I14) -> 45 | K14: =IF(E14<=0,"STOCK-OUT",IF(E14<=J14,"REORDER NOW",IF(E14<=J14*(1+Settings!$B$10),"APPROACHING","OK"))) -> STOCK-OUT | L14: =IF(OR(K14="STOCK-OUT",K14="REORDER NOW"),MAX(0,ROUNDUP(F14*Settings!$B$9-E14,0)),0) -> 126 | M14: =Products!F11 -> 7700 | N14: =L14*M14 -> 970200 | O14: =IF(K14="STOCK-OUT",REPT("█",3),IF(K14="REORDER NOW",REPT("█",6),IF(K14="APPROACHING",REPT("█",9),REPT("█",12)))) -> ███
A15: =Products!A12 -> NDL003 | B15: =Products!B12 -> Spaghetti 500g | C15: =Products!D12 -> Mushin Noodles & Foods Ltd | D15: =Products!H12 -> 3 | E15: =IF(Register!K12="",Register!J12,Register!K12) -> 24 | F15: =Register!G12/Settings!$B$6 -> 2 | G15: =IF(F15=0,"n/a",E15/F15) -> 12 | H15: =ROUNDUP(F15*(D15+Settings!$B$8),0) -> 10 | J15: =IF(I15="",H15,I15) -> 10 | K15: =IF(E15<=0,"STOCK-OUT",IF(E15<=J15,"REORDER NOW",IF(E15<=J15*(1+Settings!$B$10),"APPROACHING","OK"))) -> OK | L15: =IF(OR(K15="STOCK-OUT",K15="REORDER NOW"),MAX(0,ROUNDUP(F15*Settings!$B$9-E15,0)),0) -> 0 | M15: =Products!F12 -> 11500 | N15: =L15*M15 -> 0 | O15: =IF(K15="STOCK-OUT",REPT("█",3),IF(K15="REORDER NOW",REPT("█",6),IF(K15="APPROACHING",REPT("█",9),REPT("█",12)))) -> ████████████
A16: =Products!A13 -> OIL001 | B16: =Products!B13 -> Vegetable Oil 5L | C16: =Products!D13 -> Ikorodu Oil Mills (Agent) | D16: =Products!H13 -> 4 | E16: =IF(Register!K13="",Register!J13,Register!K13) -> 21 | F16: =Register!G13/Settings!$B$6 -> 4 | G16: =IF(F16=0,"n/a",E16/F16) -> 5.25 | H16: =ROUNDUP(F16*(D16+Settings!$B$8),0) -> 24 | J16: =IF(I16="",H16,I16) -> 24 | K16: =IF(E16<=0,"STOCK-OUT",IF(E16<=J16,"REORDER NOW",IF(E16<=J16*(1+Settings!$B$10),"APPROACHING","OK"))) -> REORDER NOW | L16: =IF(OR(K16="STOCK-OUT",K16="REORDER NOW"),MAX(0,ROUNDUP(F16*Settings!$B$9-E16,0)),0) -> 35 | M16: =Products!F13 -> 38000 | N16: =L16*M16 -> 1330000 | O16: =IF(K16="STOCK-OUT",REPT("█",3),IF(K16="REORDER NOW",REPT("█",6),IF(K16="APPROACHING",REPT("█",9),REPT("█",12)))) -> ██████
A17: =Products!A14 -> OIL002 | B17: =Products!B14 -> Vegetable Oil 1L | C17: =Products!D14 -> Ikorodu Oil Mills (Agent) | D17: =Products!H14 -> 4 | E17: =IF(Register!K14="",Register!J14,Register!K14) -> 17 | F17: =Register!G14/Settings!$B$6 -> 1.6666667 | G17: =IF(F17=0,"n/a",E17/F17) -> 10.2 | H17: =ROUNDUP(F17*(D17+Settings!$B$8),0) -> 10 | J17: =IF(I17="",H17,I17) -> 10 | K17: =IF(E17<=0,"STOCK-OUT",IF(E17<=J17,"REORDER NOW",IF(E17<=J17*(1+Settings!$B$10),"APPROACHING","OK"))) -> OK | L17: =IF(OR(K17="STOCK-OUT",K17="REORDER NOW"),MAX(0,ROUNDUP(F17*Settings!$B$9-E17,0)),0) -> 0 | M17: =Products!F14 -> 36000 | N17: =L17*M17 -> 0 | O17: =IF(K17="STOCK-OUT",REPT("█",3),IF(K17="REORDER NOW",REPT("█",6),IF(K17="APPROACHING",REPT("█",9),REPT("█",12)))) -> ████████████
